<sdf version='1.9'>
  <model name='ai_car1'>
    <link name='base_link'>
      <inertial>
        <pose>8.303983839925824e-05 0.1042785717855745 0.1992594640578478 0 0 0</pose>
        <mass>47.020000000000003</mass>
        <inertia>
          <ixx>8.1856642764526502</ixx>
          <ixy>-0.0045814878675233539</ixy>
          <ixz>-0.0010968406792010289</ixz>
          <iyy>2.432393102900813</iyy>
          <iyz>-1.3773747842990081</iyz>
          <izz>7.5653604702764774</izz>
        </inertia>
      </inertial>
      <collision name='base_link_fixed_joint_lump__chassis_collision_collision'>
        <pose>0 0 0.15 0 0 1.57</pose>
        <geometry>
          <mesh>
            <scale>1 1 1</scale>
            <uri>model://simulator/models/ai_car1/meshes/AIF_body.dae</uri>
          </mesh>
        </geometry>
      </collision>
      <collision name='base_link_fixed_joint_lump__motor_collision_collision_1'>
        <pose>0.0005574286975132958 0.6999997780522842 0.48 0 0 1.57</pose>
        <geometry>
          <mesh>
            <scale>0.001 0.001 0.001</scale>
            <uri>model://simulator/models/ai_car1/meshes/motor.dae</uri>
          </mesh>
        </geometry>
      </collision>
      <visual name='base_link_fixed_joint_lump__chassis_visual_visual'>
        <pose>0 0 0.15 0 0 1.57</pose>
        <geometry>
          <mesh>
            <scale>1 1 1</scale>
            <uri>model://simulator/models/ai_car1/meshes/AIF_body.dae</uri>
          </mesh>
        </geometry>
      </visual>
      <visual name='base_link_fixed_joint_lump__motor_visual_visual_1'>
        <pose>0.0005574286975132958 0.6999997780522842 0.48 0 0 1.57</pose>
        <geometry>
          <mesh>
            <scale>0.001 0.001 0.001</scale>
            <uri>model://simulator/models/ai_car1/meshes/motor.dae</uri>
          </mesh>
        </geometry>
      </visual>
      <sensor name='camera_depth_sensor' type='depth'>
        <update_rate>60</update_rate>
        <always_on>true</always_on>
        <visualize>true</visualize>
        <topic>depth_image_raw</topic>
        <camera name='camera'>
          <horizontal_fov>1.9198599999999999</horizontal_fov>
          <image>
            <width>480</width>
            <height>300</height>
            <format>R8G8B8</format>
          </image>
          <clip>
            <near>0.02</near>
            <far>20</far>
          </clip>
          <vertical_fov>1.39626</vertical_fov>
        </camera>
        <pose>0.000278714 0.35 0.7 0 -0 1.57</pose>
        <pointcloud>
          <topic>depth_points</topic>
        </pointcloud>
      </sensor>
      <sensor name='camera_rgb_sensor' type='camera'>
        <update_rate>60</update_rate>
        <always_on>true</always_on>
        <visualize>true</visualize>
        <topic>image_raw</topic>
        <camera name='camera'>
          <horizontal_fov>1.9198599999999999</horizontal_fov>
          <image>
            <width>480</width>
            <height>300</height>
            <format>R8G8B8</format>
          </image>
          <clip>
            <near>0.02</near>
            <far>300</far>
          </clip>
          <vertical_fov>1.39626</vertical_fov>
        </camera>
        <pose>0.000278714 0.35 0.7 0 -0 1.57</pose>
      </sensor>
      <sensor name='gps_sensor' type='navsat'>
        <always_on>true</always_on>
        <update_rate>1</update_rate>
        <topic>navsat</topic>
        <pose>0 0 0.15 0 -0 1.57</pose>
      </sensor>
      <sensor name='imu_sensor' type='imu'>
        <always_on>true</always_on>
        <update_rate>20</update_rate>
        <visualize>true</visualize>
        <topic>imu_raw</topic>
        <pose>-2.54825e-05 -0.032 0.218 0 -0 1.57</pose>
      </sensor>
    </link>
    <joint name='caster_yaw_wheel' type='revolute'>
      <pose relative_to='base_link'>0.0005574286975132958 0.6999997780522842 0.4 0 0 1.57</pose>
      <parent>base_link</parent>
      <child>caster_yaw</child>
      <axis>
        <xyz>0 0 1</xyz>
        <limit>
          <lower>-0.26000000000000001</lower>
          <upper>0.26000000000000001</upper>
          <effort>100</effort>
          <velocity>1</velocity>
        </limit>
        <dynamics>
          <damping>10</damping>
          <friction>0</friction>
          <spring_reference>0</spring_reference>
          <spring_stiffness>0</spring_stiffness>
        </dynamics>
      </axis>
    </joint>
    <link name='caster_yaw'>
      <pose relative_to='caster_yaw_wheel'>0 0 0 0 0 0</pose>
      <inertial>
        <pose>0 0 0 0 0 0</pose>
        <mass>5</mass>
        <inertia>
          <ixx>0.001</ixx>
          <ixy>0</ixy>
          <ixz>0</ixz>
          <iyy>0.001</iyy>
          <iyz>0</iyz>
          <izz>0.001</izz>
        </inertia>
      </inertial>
      <collision name='caster_yaw_collision'>
        <pose>0 0 0 0 0 0</pose>
        <geometry>
          <mesh>
            <scale>0.001 0.001 0.001</scale>
            <uri>model://simulator/models/ai_car1/meshes/castor_yaw.dae</uri>
          </mesh>
        </geometry>
      </collision>
      <visual name='caster_yaw_visual'>
        <pose>0 0 0 0 0 0</pose>
        <geometry>
          <mesh>
            <scale>0.001 0.001 0.001</scale>
            <uri>model://simulator/models/ai_car1/meshes/castor_yaw.dae</uri>
          </mesh>
        </geometry>
        <material>
          <diffuse>1 0 0 1</diffuse>
          <ambient>1 0 0 1</ambient>
        </material>
      </visual>
    </link>
    <joint name='caster_pitch_joint' type='revolute'>
      <pose relative_to='caster_yaw'>0.1 0 -0.25 0 0 1.57</pose>
      <parent>caster_yaw</parent>
      <child>caster</child>
      <axis>
        <xyz>1 0 0</xyz>
        <limit>
          <lower>-10000000000000000</lower>
          <upper>10000000000000000</upper>
        </limit>
        <dynamics>
          <damping>0.01</damping>
          <friction>0</friction>
          <spring_reference>0</spring_reference>
          <spring_stiffness>0</spring_stiffness>
        </dynamics>
      </axis>
    </joint>
    <link name='caster'>
      <pose relative_to='caster_pitch_joint'>0 0 0 0 0 0</pose>
      <inertial>
        <pose>0 0 0 0 0 0</pose>
        <mass>1</mass>
        <inertia>
          <ixx>0.047780000000000003</ixx>
          <ixy>0</ixy>
          <ixz>0</ixz>
          <iyy>0.047780000000000003</iyy>
          <iyz>0</iyz>
          <izz>0.078750000000000001</izz>
        </inertia>
      </inertial>
      <collision name='caster_collision'>
        <pose>0 0 0 0 0 0</pose>
        <geometry>
          <mesh>
            <scale>0.1 0.1 0.1</scale>
            <uri>model://simulator/models/ai_car1/meshes/tire.dae</uri>
          </mesh>
        </geometry>
      </collision>
      <visual name='caster_visual'>
        <pose>0 0 0 0 0 0</pose>
        <geometry>
          <mesh>
            <scale>0.1 0.1 0.1</scale>
            <uri>model://simulator/models/ai_car1/meshes/tire.dae</uri>
          </mesh>
        </geometry>
      </visual>
    </link>
    <joint name='left_wheel_joint' type='revolute'>
      <pose relative_to='base_link'>0.2999999048795504 -0.0002388980132199681 0.15 1.57 1.799775606325937e-17 3.14</pose>
      <parent>base_link</parent>
      <child>left_wheel</child>
      <axis>
        <xyz>-1 0 0</xyz>
        <limit>
          <lower>-1000</lower>
          <upper>1000</upper>
          <effort>9.4000000000000004</effort>
          <velocity>100</velocity>
        </limit>
        <dynamics>
          <damping>0</damping>
          <friction>0.90000000000000002</friction>
          <spring_reference>0</spring_reference>
          <spring_stiffness>0</spring_stiffness>
        </dynamics>
      </axis>
    </joint>
    <link name='left_wheel'>
      <pose relative_to='left_wheel_joint'>0 0 0 0 0 0</pose>
      <inertial>
        <pose>0 0 0 0 0 0</pose>
        <mass>7</mass>
        <inertia>
          <ixx>0.047780000000000003</ixx>
          <ixy>0</ixy>
          <ixz>0</ixz>
          <iyy>0.047780000000000003</iyy>
          <iyz>0</iyz>
          <izz>0.078750000000000001</izz>
        </inertia>
      </inertial>
      <collision name='left_wheel_collision_collision'>
        <pose>0 0 0 0 0 0</pose>
        <geometry>
          <mesh>
            <scale>0.05 0.12 0.12</scale>
            <uri>model://simulator/models/ai_car1/meshes/tire.dae</uri>
          </mesh>
        </geometry>
      </collision>
      <visual name='left_wheel_visual_visual'>
        <pose>0 0 0 0 0 0</pose>
        <geometry>
          <mesh>
            <scale>0.05 0.12 0.12</scale>
            <uri>model://simulator/models/ai_car1/meshes/tire.dae</uri>
          </mesh>
        </geometry>
      </visual>
    </link>
    <joint name='motor_spin_joint' type='revolute'>
      <pose relative_to='base_link'>0.0005574286975132958 0.6999997780522842 0.502 0 0 1.57</pose>
      <parent>base_link</parent>
      <child>motor_spin</child>
      <axis>
        <xyz>0 0 1</xyz>
        <limit>
          <lower>-6.2830000000000004</lower>
          <upper>6.2830000000000004</upper>
          <effort>9.4000000000000004</effort>
          <velocity>100</velocity>
        </limit>
        <dynamics>
          <damping>0</damping>
          <friction>0.90000000000000002</friction>
          <spring_reference>0</spring_reference>
          <spring_stiffness>0</spring_stiffness>
        </dynamics>
      </axis>
    </joint>
    <link name='motor_spin'>
      <pose relative_to='motor_spin_joint'>0 0 0 0 0 0</pose>
      <inertial>
        <pose>0 0 0 0 0 0</pose>
        <mass>7</mass>
        <inertia>
          <ixx>0.047780000000000003</ixx>
          <ixy>0</ixy>
          <ixz>0</ixz>
          <iyy>0.047780000000000003</iyy>
          <iyz>0</iyz>
          <izz>0.078750000000000001</izz>
        </inertia>
      </inertial>
      <collision name='motor_spin_collision_collision'>
        <pose>0 0 0 0 0 0</pose>
        <geometry>
          <mesh>
            <scale>0.001 0.001 0.001</scale>
            <uri>model://simulator/models/ai_car1/meshes/motor_spin.dae</uri>
          </mesh>
        </geometry>
      </collision>
      <visual name='motor_spin_visual_visual'>
        <pose>0 0 0 0 0 0</pose>
        <geometry>
          <mesh>
            <scale>0.001 0.001 0.001</scale>
            <uri>model://simulator/models/ai_car1/meshes/motor_spin.dae</uri>
          </mesh>
        </geometry>
        <material>
          <diffuse>1 1 0 1</diffuse>
          <ambient>1 1 0 1</ambient>
        </material>
      </visual>
    </link>
    <joint name='right_wheel_joint' type='revolute'>
      <pose relative_to='base_link'>-0.2999999048795504 0.0002388980132199681 0.15 1.57 1.799775606325937e-17 3.14</pose>
      <parent>base_link</parent>
      <child>right_wheel</child>
      <axis>
        <xyz>-1 0 0</xyz>
        <limit>
          <lower>-1000</lower>
          <upper>1000</upper>
          <effort>9.4000000000000004</effort>
          <velocity>100</velocity>
        </limit>
        <dynamics>
          <damping>0</damping>
          <friction>0.90000000000000002</friction>
          <spring_reference>0</spring_reference>
          <spring_stiffness>0</spring_stiffness>
        </dynamics>
      </axis>
    </joint>
    <link name='right_wheel'>
      <pose relative_to='right_wheel_joint'>0 0 0 0 0 0</pose>
      <inertial>
        <pose>0 0 0 0 0 0</pose>
        <mass>7</mass>
        <inertia>
          <ixx>0.047780000000000003</ixx>
          <ixy>0</ixy>
          <ixz>0</ixz>
          <iyy>0.047780000000000003</iyy>
          <iyz>0</iyz>
          <izz>0.078750000000000001</izz>
        </inertia>
      </inertial>
      <collision name='right_wheel_collision_collision'>
        <pose>0 0 0 0 0 0</pose>
        <geometry>
          <mesh>
            <scale>0.05 0.12 0.12</scale>
            <uri>model://simulator/models/ai_car1/meshes/tire.dae</uri>
          </mesh>
        </geometry>
      </collision>
      <visual name='right_wheel_visual_visual'>
        <pose>0 0 0 0 0 0</pose>
        <geometry>
          <mesh>
            <scale>0.05 0.12 0.12</scale>
            <uri>model://simulator/models/ai_car1/meshes/tire.dae</uri>
          </mesh>
        </geometry>
      </visual>
    </link>
    <plugin name='ignition::gazebo::systems::DiffDrive' filename='libignition-gazebo-diff-drive-system.so'>
      <left_joint>left_wheel_joint</left_joint>
      <right_joint>right_wheel_joint</right_joint>
      <wheel_separation>0.6</wheel_separation>
      <wheel_radius>0.124</wheel_radius>
      <odom_publish_frequency>30</odom_publish_frequency>
      <topic>cmd_vel</topic>
      <odom_topic>odom</odom_topic>
    </plugin>
    <plugin name='ignition_imu' filename='libignition-gazebo-imu-system.so'/>
    <plugin name='ignition_sensors' filename='ignition-gazebo-sensors-system'/>
    <plugin name='gz_ros2_control::GazeboSimROS2ControlPlugin' filename='gz_ros2_control-system'>
      <parameters>/home/ikenta/ros2_ws/src/aiformula/simulator/config/8108_effort_controller.yaml</parameters>
    </plugin>
    <frame name='camera_depth_joint' attached_to='camera_link'>
      <pose>0 0 0 0 -0 0</pose>
    </frame>
    <frame name='camera_depth_link' attached_to='camera_depth_joint'/>
    <frame name='camera_rgb_joint' attached_to='camera_link'>
      <pose>0 0 0 0 -0 0</pose>
    </frame>
    <frame name='camera_rgb_link' attached_to='camera_rgb_joint'/>
    <frame name='camera_joint' attached_to='chassis'>
      <pose>0.35 0 0.55 0 -0 0</pose>
    </frame>
    <frame name='camera_link' attached_to='camera_joint'/>
    <frame name='gps_joint' attached_to='chassis'>
      <pose>0 0 0 0 -0 0</pose>
    </frame>
    <frame name='gps_link' attached_to='gps_joint'/>
    <frame name='imu_joint' attached_to='chassis'>
      <pose>-0.032 0 0.068 0 -0 0</pose>
    </frame>
    <frame name='imu_link' attached_to='imu_joint'/>
    <frame name='motor_joint' attached_to='chassis'>
      <pose>0.7 0 0.33 0 -0 0</pose>
    </frame>
    <frame name='motor' attached_to='motor_joint'/>
    <frame name='chassis_offset_joint' attached_to='base_link'>
      <pose>0 0 0.15 0 -0 1.57</pose>
    </frame>
    <frame name='chassis' attached_to='chassis_offset_joint'/>
  </model>
</sdf>
